Workbook

Sheet DRE
A3: BAR LEO | H3: =J8/H8 -> 1.1349048 | J3: =J8/I8 -> 1.0317316 | K3: =M8/K8 -> 1.0260133 | M3: =M8/L8 -> 0.89218552 | N3: =P8/N8 -> 1.0889138 | P3: =P8/O8 -> 1.1836019 | Q3: =S8/Q8 -> 1.1210415 | S3: =S8/R8 -> 1.2456016 | T3: =V8/T8 -> 0.85507486 | V3: =V8/U8 -> 0.77033771 | Y3: =Y8/X8 -> 0.83320363 | AB3: =AB8/AA8 -> 0.18377506 | AE3: =AE8/AD8 -> 0 | AH3: =AH8/AG8 -> 0 | AK3: =AK8/AJ8 -> 0 | AN3: =AN8/AM8 -> 0 | AQ3: =AQ8/AP8 -> 0 | AR3: =AT8/AR8 -> 1.0417289 | AT3: =AT8/AS8 -> 0.96212556
H4: 46023 | K4: 46054 | N4: 46082 | Q4: 46113 | T4: 46143 | W4: 46174 | Z4: 46204 | AC4: 46235 | AF4: 46266 | AI4: 46296 | AL4: 46327 | AO4: 46357 | AR4: Acumulado | AU4: ANO | AX4: 1º TRIMESTRE | BA4: 2º TRIMESTRE | BD4: 3º TRIMESTRE | BG4: 4º TRIMESTRE
H5: 1 | I5: 1 | J5: =MONTH(H4) -> 1 | K5: 2 | L5: 2 | M5: =MONTH(K4) -> 2 | N5: 3 | O5: 3 | P5: =MONTH(N4) -> 3 | Q5: 4 | R5: 4 | S5: =MONTH(Q4) -> 4 | T5: 5 | U5: 5 | V5: =MONTH(T4) -> 5 | W5: 6 | X5: 6 | Y5: =MONTH(W4) -> 6 | Z5: 7 | AA5: 7 | AB5: =MONTH(Z4) -> 7 | AC5: 8 | AD5: 8 | AE5: =MONTH(AC4) -> 8 | AF5: 9 | AG5: 9 | AH5: =MONTH(AF4) -> 9 | AI5: 10 | AJ5: 10 | AK5: =MONTH(AI4) -> 10 | AL5: 11 | AM5: 11 | AN5: =MONTH(AL4) -> 11 | AO5: 12 | AP5: 12 | AQ5: =MONTH(AO4) -> 12
H6: REAL 25 | I6: ORÇADO | J6: REAL 26 | K6: REAL 25 | L6: ORÇADO | M6: REAL 26 | N6: REAL 25 | O6: ORÇADO | P6: REAL 26 | Q6: REAL 25 | R6: ORÇADO | S6: REAL 26 | T6: REAL 25 | U6: ORÇADO | V6: REAL 26 | W6: REAL 25 | X6: ORÇADO | Y6: REAL 26 | Z6: REAL 25 | AA6: ORÇADO | AB6: REAL 26 | AC6: REAL 25 | AD6: ORÇADO | AE6: REAL 26 | AF6: REAL 25 | AG6: ORÇADO | AH6: REAL 26 | AI6: REAL 25 | AJ6: ORÇADO | AK6: REAL 26 | AL6: REAL 25 | AM6: ORÇADO | AN6: REAL 26 | AO6: REAL 25 | AP6: ORÇADO | AQ6: REAL 26 | AR6: 2025 | AS6: ORÇADO | AT6: REAL 2026 | AU6: 2025 | AV6: ORÇADO | AW6: REAL 2026 | AX6: REAL 25 | AY6: ORÇADO | AZ6: REAL 26 | BA6: REAL 25 | BB6: ORÇADO | BC6: REAL 26 | BD6: REAL 25 | BE6: ORÇADO | BF6: REAL 26 | BG6: REAL 25 | BH6: ORÇADO | BI6: REAL 26
H7: 45658 | I7: 46023 | K7: 45689 | L7: 46054 | N7: 45717 | Q7: 45748 | T7: 45778 | W7: 45809 | Z7: 45839 | AC7: 45870 | AF7: 45901 | AI7: 45931 | AL7: 45962 | AO7: 45992 | BK7: Validação orçado | BM7: Validação real
A8: FATURAMENTO BRUTO | C8: PARÂMETROS UTILIZADOS | H8: 340452.79 | I8: 374498.07 | J8: =SUM(J9:J19)+SUMIFS(Aut_Ajustes_Manuais!$G:$G,Aut_Ajustes_Manuais!$I:$I,DRE!H$4,Aut_Ajustes_Manuais!$F:$F,"FATURAMENTO BRUTO") -> 386381.5 | K8: 308971.38 | L8: 355317.09 | M8: =SUM(M9:M19)+SUMIFS(Aut_Ajustes_Manuais!$G:$G,Aut_Ajustes_Manuais!$I:$I,DRE!K$4,Aut_Ajustes_Manuais!$F:$F,"FATURAMENTO BRUTO") -> 317008.76 | N8: 309840.35 | O8: 285053.12 | P8: =SUM(P9:P19)+SUMIFS(Aut_Ajustes_Manuais!$G:$G,Aut_Ajustes_Manuais!$I:$I,DRE!N$4,Aut_Ajustes_Manuais!$F:$F,"FATURAMENTO BRUTO") -> 337389.43 | Q8: 329611.99 | R8: 296650.79 | S8: =SUM(S9:S19)+SUMIFS(Aut_Ajustes_Manuais!$G:$G,Aut_Ajustes_Manuais!$I:$I,DRE!Q$4,Aut_Ajustes_Manuais!$F:$F,"FATURAMENTO BRUTO") -> 369508.71 | T8: 435998.13 | U8: 483957.92 | V8: =SUM(V9:V19)+SUMIFS(Aut_Ajustes_Manuais!$G:$G,Aut_Ajustes_Manuais!$I:$I,DRE!T$4,Aut_Ajustes_Manuais!$F:$F,"FATURAMENTO BRUTO") -> 372811.04 | W8: 331895.17 | X8: 431463.72 | Y8: =SUM(Y9:Y19)+SUMIFS(Aut_Ajustes_Manuais!$G:$G,Aut_Ajustes_Manuais!$I:$I,DRE!W$4,Aut_Ajustes_Manuais!$F:$F,"FATURAMENTO BRUTO") -> 359497.14 | Z8: 356143.63 | AA8: 427372.36 | AB8: =SUM(AB9:AB19)+SUMIFS(Aut_Ajustes_Manuais!$G:$G,Aut_Ajustes_Manuais!$I:$I,DRE!Z$4,Aut_Ajustes_Manuais!$F:$F,"FATURAMENTO BRUTO") -> 78540.38 | AC8: 415517.46 | AD8: 461224.38 | AE8: =SUM(AE9:AE19)+SUMIFS(Aut_Ajustes_Manuais!$G:$G,Aut_Ajustes_Manuais!$I:$I,DRE!AC$4,Aut_Ajustes_Manuais!$F:$F,"FATURAMENTO BRUTO") -> 0 | AF8: 352535.84 | AG8: 401890.86 | AH8: =SUM(AH9:AH19)+SUMIFS(Aut_Ajustes_Manuais!$G:$G,Aut_Ajustes_Manuais!$I:$I,DRE!AF$4,Aut_Ajustes_Manuais!$F:$F,"FATURAMENTO BRUTO") -> 0 | AI8: 362912.76 | AJ8: 404425.97 | AK8: =SUM(AK9:AK19)+SUMIFS(Aut_Ajustes_Manuais!$G:$G,Aut_Ajustes_Manuais!$I:$I,DRE!AI$4,Aut_Ajustes_Manuais!$F:$F,"FATURAMENTO BRUTO") -> 0 | AL8: 429533.42 | AM8: 469333.44 | AN8: =SUM(AN9:AN19)+SUMIFS(Aut_Ajustes_Manuais!$G:$G,Aut_Ajustes_Manuais!$I:$I,DRE!AL$4,Aut_Ajustes_Manuais!$F:$F,"FATURAMENTO BRUTO") -> 0 | AO8: 480232.62 | AP8: 424800 | AQ8: =SUM(AQ9:AQ19)+SUMIFS(Aut_Ajustes_Manuais!$G:$G,Aut_Ajustes_Manuais!$I:$I,DRE!AO$4,Aut_Ajustes_Manuais!$F:$F,"FATURAMENTO BRUTO") -> 0 | AR8: =SUM(AR9:AR19) -> 2056769.8 | AS8: =SUM(AS9:AS19) -> 2226940.7 | AT8: =SUM(AT9:AT19) -> 2142596.6 | AU8: =SUM(AU9:AU19) -> 4453645.5 | AV8: =SUM(AV9:AV19) -> 4815987.7 | AW8: =SUM(AW9:AW19) -> 2221137 | AX8: =SUM(AX9:AX19) -> 959264.52 | AY8: =SUM(AY9:AY19) -> 1014868.3 | ... BI8: =SUM(BI9:BI19) -> 0 | BK8: =SUM(I8,L8,O8,R8,U8,X8,AA8,AD8,AG8,AJ8,AM8,AP8) -> 4815987.7 | BL8: =BK8-AV8 -> 0 | BM8: =SUM(J8,M8,P8,S8,V8) -> 1783099.4 | BN8: =BM8-AT8 -> -359497.14
A9: Alimentação | C9: Estim. Mensal | D9: Preencher base de Faturamento A&B&C | H9: 143346 | I9: 118996.39 | J9: =SUMIFS(Aut_Faturamento_Zig!$F:$F,Aut_Faturamento_Zig!$E:$E,"Alimentos",Aut_Faturamento_Zig!$D:$D,DRE!H$4)-SUMIFS(Aut_Promocoes_Utilizadas!$G:$G,Aut_Promocoes_Utilizadas!$J:$J,DRE!H$4,Aut_Promocoes_Utilizadas!$H:$H,"A",Aut_Promocoes_Utilizadas!$I:$I,"Eventos")-SUMIFS(Aut_Descontos!$I:$I,Aut_Descontos!$L:$L,DRE!H$4)-(SUMIFS(BD_Eventos_Novo!$J:$J,BD_Eventos_Novo!$AB:$AB,DRE!H$4,BD_Eventos_Novo!$G:$G,"Consumação Mínima")*50%)-(SUMIFS(BD_Eventos_Novo!$K:$K,BD_Eventos_Novo!$AB:$AB,DRE!H$4,BD_Eventos_Novo!$G:$G,"Consumação Mínima")*50%)-(SUMIFS(BD_Eventos_Novo!$J:$J,BD_Eventos_Novo!$AB:$AB,DRE!H$4,BD_Eventos_Novo!$G:$G,"Comanda Aberta / Couvert Antecipado")*50%)-(SUMIFS(BD_Eventos_Novo!$K:$K,BD_Eventos_Novo!$AB:$AB,DRE!H$4,BD_Eventos_Novo!$G:$G,"Comanda Aberta / Couvert Antecipado")*50%)+SUMIFS(Aut_Ajustes_Manuais!$G:$G,Aut_Ajustes_Manuais!$I:$I,DRE!H$4,Aut_Ajustes_Manuais!$F:$F,"Alimentação") -> 150801.5 | K9: 132728.5 | L9: 112901.65 | M9: =SUMIFS(Aut_Faturamento_Zig!$F:$F,Aut_Faturamento_Zig!$E:$E,"Alimentos",Aut_Faturamento_Zig!$D:$D,DRE!K$4)-SUMIFS(Aut_Promocoes_Utilizadas!$G:$G,Aut_Promocoes_Utilizadas!$J:$J,DRE!K$4,Aut_Promocoes_Utilizadas!$H:$H,"A",Aut_Promocoes_Utilizadas!$I:$I,"Eventos")-SUMIFS(Aut_Descontos!$I:$I,Aut_Descontos!$L:$L,DRE!K$4)-(SUMIFS(BD_Eventos_Novo!$J:$J,BD_Eventos_Novo!$AB:$AB,DRE!K$4,BD_Eventos_Novo!$G:$G,"Consumação Mínima")*50%)-(SUMIFS(BD_Eventos_Novo!$K:$K,BD_Eventos_Novo!$AB:$AB,DRE!K$4,BD_Eventos_Novo!$G:$G,"Consumação Mínima")*50%)-(SUMIFS(BD_Eventos_Novo!$J:$J,BD_Eventos_Novo!$AB:$AB,DRE!K$4,BD_Eventos_Novo!$G:$G,"Comanda Aberta / Couvert Antecipado")*50%)-(SUMIFS(BD_Eventos_Novo!$K:$K,BD_Eventos_Novo!$AB:$AB,DRE!K$4,BD_Eventos_Novo!$G:$G,"Comanda Aberta / Couvert Antecipado")*50%)+SUMIFS(Aut_Ajustes_Manuais!$G:$G,Aut_Ajustes_Manuais!$I:$I,DRE!K$4,Aut_Ajustes_Manuais!$F:$F,"Alimentação") -> 125404.4 | N9: 131478.5 | O9: 90575.348 | P9: =SUMIFS(Aut_Faturamento_Zig!$F:$F,Aut_Faturamento_Zig!$E:$E,"Alimentos",Aut_Faturamento_Zig!$D:$D,DRE!N$4)-SUMIFS(Aut_Promocoes_Utilizadas!$G:$G,Aut_Promocoes_Utilizadas!$J:$J,DRE!N$4,Aut_Promocoes_Utilizadas!$H:$H,"A",Aut_Promocoes_Utilizadas!$I:$I,"Eventos")-SUMIFS(Aut_Descontos!$I:$I,Aut_Descontos!$L:$L,DRE!N$4)-(SUMIFS(BD_Eventos_Novo!$J:$J,BD_Eventos_Novo!$AB:$AB,DRE!N$4,BD_Eventos_Novo!$G:$G,"Consumação Mínima")*50%)-(SUMIFS(BD_Eventos_Novo!$K:$K,BD_Eventos_Novo!$AB:$AB,DRE!N$4,BD_Eventos_Novo!$G:$G,"Consumação Mínima")*50%)-(SUMIFS(BD_Eventos_Novo!$J:$J,BD_Eventos_Novo!$AB:$AB,DRE!N$4,BD_Eventos_Novo!$G:$G,"Comanda Aberta / Couvert Antecipado")*50%)-(SUMIFS(BD_Eventos_Novo!$K:$K,BD_Eventos_Novo!$AB:$AB,DRE!N$4,BD_Eventos_Novo!$G:$G,"Comanda Aberta / Couvert Antecipado")*50%)+SUMIFS(Aut_Ajustes_Manuais!$G:$G,Aut_Ajustes_Manuais!$I:$I,DRE!N$4,Aut_Ajustes_Manuais!$F:$F,"Alimentação") -> 134559.5 | Q9: 144072 | R9: 94260.496 | S9: =SUMIFS(Aut_Faturamento_Zig!$F:$F,Aut_Faturamento_Zig!$E:$E,"Alimentos",Aut_Faturamento_Zig!$D:$D,DRE!Q$4)-SUMIFS(Aut_Promocoes_Utilizadas!$G:$G,Aut_Promocoes_Utilizadas!$J:$J,DRE!Q$4,Aut_Promocoes_Utilizadas!$H:$H,"A",Aut_Promocoes_Utilizadas!$I:$I,"Eventos")-SUMIFS(Aut_Descontos!$I:$I,Aut_Descontos!$L:$L,DRE!Q$4)-(SUMIFS(BD_Eventos_Novo!$J:$J,BD_Eventos_Novo!$AB:$AB,DRE!Q$4,BD_Eventos_Novo!$G:$G,"Consumação Mínima")*50%)-(SUMIFS(BD_Eventos_Novo!$K:$K,BD_Eventos_Novo!$AB:$AB,DRE!Q$4,BD_Eventos_Novo!$G:$G,"Consumação Mínima")*50%)-(SUMIFS(BD_Eventos_Novo!$J:$J,BD_Eventos_Novo!$AB:$AB,DRE!Q$4,BD_Eventos_Novo!$G:$G,"Comanda Aberta / Couvert Antecipado")*50%)-(SUMIFS(BD_Eventos_Novo!$K:$K,BD_Eventos_Novo!$AB:$AB,DRE!Q$4,BD_Eventos_Novo!$G:$G,"Comanda Aberta / Couvert Antecipado")*50%)+SUMIFS(Aut_Ajustes_Manuais!$G:$G,Aut_Ajustes_Manuais!$I:$I,DRE!Q$4,Aut_Ajustes_Manuais!$F:$F,"Alimentação") -> 147447.9 | T9: 185616.1 | U9: 153777.15 | V9: =SUMIFS(Aut_Faturamento_Zig!$F:$F,Aut_Faturamento_Zig!$E:$E,"Alimentos",Aut_Faturamento_Zig!$D:$D,DRE!T$4)-SUMIFS(Aut_Promocoes_Utilizadas!$G:$G,Aut_Promocoes_Utilizadas!$J:$J,DRE!T$4,Aut_Promocoes_Utilizadas!$H:$H,"A",Aut_Promocoes_Utilizadas!$I:$I,"Eventos")-SUMIFS(Aut_Descontos!$I:$I,Aut_Descontos!$L:$L,DRE!T$4)-(SUMIFS(BD_Eventos_Novo!$J:$J,BD_Eventos_Novo!$AB:$AB,DRE!T$4,BD_Eventos_Novo!$G:$G,"Consumação Mínima")*50%)-(SUMIFS(BD_Eventos_Novo!$K:$K,BD_Eventos_Novo!$AB:$AB,DRE!T$4,BD_Eventos_Novo!$G:$G,"Consumação Mínima")*50%)-(SUMIFS(BD_Eventos_Novo!$J:$J,BD_Eventos_Novo!$AB:$AB,DRE!T$4,BD_Eventos_Novo!$G:$G,"Comanda Aberta / Couvert Antecipado")*50%)-(SUMIFS(BD_Eventos_Novo!$K:$K,BD_Eventos_Novo!$AB:$AB,DRE!T$4,BD_Eventos_Novo!$G:$G,"Comanda Aberta / Couvert Antecipado")*50%)+SUMIFS(Aut_Ajustes_Manuais!$G:$G,Aut_Ajustes_Manuais!$I:$I,DRE!T$4,Aut_Ajustes_Manuais!$F:$F,"Alimentação") -> 154905.5 | W9: 141881.5 | X9: 137097.17 | Y9: =SUMIFS(Aut_Faturamento_Zig!$F:$F,Aut_Faturamento_Zig!$E:$E,"Alimentos",Aut_Faturamento_Zig!$D:$D,DRE!W$4)-SUMIFS(Aut_Promocoes_Utilizadas!$G:$G,Aut_Promocoes_Utilizadas!$J:$J,DRE!W$4,Aut_Promocoes_Utilizadas!$H:$H,"A",Aut_Promocoes_Utilizadas!$I:$I,"Eventos")-SUMIFS(Aut_Descontos!$I:$I,Aut_Descontos!$L:$L,DRE!W$4)-(SUMIFS(BD_Eventos_Novo!$J:$J,BD_Eventos_Novo!$AB:$AB,DRE!W$4,BD_Eventos_Novo!$G:$G,"Consumação Mínima")*50%)-(SUMIFS(BD_Eventos_Novo!$K:$K,BD_Eventos_Novo!$AB:$AB,DRE!W$4,BD_Eventos_Novo!$G:$G,"Consumação Mínima")*50%)-(SUMIFS(BD_Eventos_Novo!$J:$J,BD_Eventos_Novo!$AB:$AB,DRE!W$4,BD_Eventos_Novo!$G:$G,"Comanda Aberta / Couvert Antecipado")*50%)-(SUMIFS(BD_Eventos_Novo!$K:$K,BD_Eventos_Novo!$AB:$AB,DRE!W$4,BD_Eventos_Novo!$G:$G,"Comanda Aberta / Couvert Antecipado")*50%)+SUMIFS(Aut_Ajustes_Manuais!$G:$G,Aut_Ajustes_Manuais!$I:$I,DRE!W$4,Aut_Ajustes_Manuais!$F:$F,"Alimentação") -> 149615.3 | Z9: 160709.8 | AA9: 135797.14 | AB9: =SUMIFS(Aut_Faturamento_Zig!$F:$F,Aut_Faturamento_Zig!$E:$E,"Alimentos",Aut_Faturamento_Zig!$D:$D,DRE!Z$4)-SUMIFS(Aut_Promocoes_Utilizadas!$G:$G,Aut_Promocoes_Utilizadas!$J:$J,DRE!Z$4,Aut_Promocoes_Utilizadas!$H:$H,"A",Aut_Promocoes_Utilizadas!$I:$I,"Eventos")-SUMIFS(Aut_Descontos!$I:$I,Aut_Descontos!$L:$L,DRE!Z$4)-(SUMIFS(BD_Eventos_Novo!$J:$J,BD_Eventos_Novo!$AB:$AB,DRE!Z$4,BD_Eventos_Novo!$G:$G,"Consumação Mínima")*50%)-(SUMIFS(BD_Eventos_Novo!$K:$K,BD_Eventos_Novo!$AB:$AB,DRE!Z$4,BD_Eventos_Novo!$G:$G,"Consumação Mínima")*50%)-(SUMIFS(BD_Eventos_Novo!$J:$J,BD_Eventos_Novo!$AB:$AB,DRE!Z$4,BD_Eventos_Novo!$G:$G,"Comanda Aberta / Couvert Antecipado")*50%)-(SUMIFS(BD_Eventos_Novo!$K:$K,BD_Eventos_Novo!$AB:$AB,DRE!Z$4,BD_Eventos_Novo!$G:$G,"Comanda Aberta / Couvert Antecipado")*50%)+SUMIFS(Aut_Ajustes_Manuais!$G:$G,Aut_Ajustes_Manuais!$I:$I,DRE!Z$4,Aut_Ajustes_Manuais!$F:$F,"Alimentação") -> 32087.5 | AC9: 169931.9 | AD9: 146553.59 | AE9: =SUMIFS(Aut_Faturamento_Zig!$F:$F,Aut_Faturamento_Zig!$E:$E,"Alimentos",Aut_Faturamento_Zig!$D:$D,DRE!AC$4)-SUMIFS(Aut_Promocoes_Utilizadas!$G:$G,Aut_Promocoes_Utilizadas!$J:$J,DRE!AC$4,Aut_Promocoes_Utilizadas!$H:$H,"A",Aut_Promocoes_Utilizadas!$I:$I,"Eventos")-SUMIFS(Aut_Descontos!$I:$I,Aut_Descontos!$L:$L,DRE!AC$4)-(SUMIFS(BD_Eventos_Novo!$J:$J,BD_Eventos_Novo!$AB:$AB,DRE!AC$4,BD_Eventos_Novo!$G:$G,"Consumação Mínima")*50%)-(SUMIFS(BD_Eventos_Novo!$K:$K,BD_Eventos_Novo!$AB:$AB,DRE!AC$4,BD_Eventos_Novo!$G:$G,"Consumação Mínima")*50%)-(SUMIFS(BD_Eventos_Novo!$J:$J,BD_Eventos_Novo!$AB:$AB,DRE!AC$4,BD_Eventos_Novo!$G:$G,"Comanda Aberta / Couvert Antecipado")*50%)-(SUMIFS(BD_Eventos_Novo!$K:$K,BD_Eventos_Novo!$AB:$AB,DRE!AC$4,BD_Eventos_Novo!$G:$G,"Comanda Aberta / Couvert Antecipado")*50%)+SUMIFS(Aut_Ajustes_Manuais!$G:$G,Aut_Ajustes_Manuais!$I:$I,DRE!AC$4,Aut_Ajustes_Manuais!$F:$F,"Alimentação") -> 0 | AF9: 149655 | AG9: 127700.42 | AH9: =SUMIFS(Aut_Faturamento_Zig!$F:$F,Aut_Faturamento_Zig!$E:$E,"Alimentos",Aut_Faturamento_Zig!$D:$D,DRE!AF$4)-SUMIFS(Aut_Promocoes_Utilizadas!$G:$G,Aut_Promocoes_Utilizadas!$J:$J,DRE!AF$4,Aut_Promocoes_Utilizadas!$H:$H,"A",Aut_Promocoes_Utilizadas!$I:$I,"Eventos")-SUMIFS(Aut_Descontos!$I:$I,Aut_Descontos!$L:$L,DRE!AF$4)-(SUMIFS(BD_Eventos_Novo!$J:$J,BD_Eventos_Novo!$AB:$AB,DRE!AF$4,BD_Eventos_Novo!$G:$G,"Consumação Mínima")*50%)-(SUMIFS(BD_Eventos_Novo!$K:$K,BD_Eventos_Novo!$AB:$AB,DRE!AF$4,BD_Eventos_Novo!$G:$G,"Consumação Mínima")*50%)-(SUMIFS(BD_Eventos_Novo!$J:$J,BD_Eventos_Novo!$AB:$AB,DRE!AF$4,BD_Eventos_Novo!$G:$G,"Comanda Aberta / Couvert Antecipado")*50%)-(SUMIFS(BD_Eventos_Novo!$K:$K,BD_Eventos_Novo!$AB:$AB,DRE!AF$4,BD_Eventos_Novo!$G:$G,"Comanda Aberta / Couvert Antecipado")*50%)+SUMIFS(Aut_Ajustes_Manuais!$G:$G,Aut_Ajustes_Manuais!$I:$I,DRE!AF$4,Aut_Ajustes_Manuais!$F:$F,"Alimentação") -> 0 | AI9: 151610.5 | AJ9: 128505.95 | AK9: =SUMIFS(Aut_Faturamento_Zig!$F:$F,Aut_Faturamento_Zig!$E:$E,"Alimentos",Aut_Faturamento_Zig!$D:$D,DRE!AI$4)-SUMIFS(Aut_Promocoes_Utilizadas!$G:$G,Aut_Promocoes_Utilizadas!$J:$J,DRE!AI$4,Aut_Promocoes_Utilizadas!$H:$H,"A",Aut_Promocoes_Utilizadas!$I:$I,"Eventos")-SUMIFS(Aut_Descontos!$I:$I,Aut_Descontos!$L:$L,DRE!AI$4)-(SUMIFS(BD_Eventos_Novo!$J:$J,BD_Eventos_Novo!$AB:$AB,DRE!AI$4,BD_Eventos_Novo!$G:$G,"Consumação Mínima")*50%)-(SUMIFS(BD_Eventos_Novo!$K:$K,BD_Eventos_Novo!$AB:$AB,DRE!AI$4,BD_Eventos_Novo!$G:$G,"Consumação Mínima")*50%)-(SUMIFS(BD_Eventos_Novo!$J:$J,BD_Eventos_Novo!$AB:$AB,DRE!AI$4,BD_Eventos_Novo!$G:$G,"Comanda Aberta / Couvert Antecipado")*50%)-(SUMIFS(BD_Eventos_Novo!$K:$K,BD_Eventos_Novo!$AB:$AB,DRE!AI$4,BD_Eventos_Novo!$G:$G,"Comanda Aberta / Couvert Antecipado")*50%)+SUMIFS(Aut_Ajustes_Manuais!$G:$G,Aut_Ajustes_Manuais!$I:$I,DRE!AI$4,Aut_Ajustes_Manuais!$F:$F,"Alimentação") -> 0 | AL9: 154679 | AM9: 149130.24 | AN9: =SUMIFS(Aut_Faturamento_Zig!$F:$F,Aut_Faturamento_Zig!$E:$E,"Alimentos",Aut_Faturamento_Zig!$D:$D,DRE!AL$4)-SUMIFS(Aut_Promocoes_Utilizadas!$G:$G,Aut_Promocoes_Utilizadas!$J:$J,DRE!AL$4,Aut_Promocoes_Utilizadas!$H:$H,"A",Aut_Promocoes_Utilizadas!$I:$I,"Eventos")-SUMIFS(Aut_Descontos!$I:$I,Aut_Descontos!$L:$L,DRE!AL$4)-(SUMIFS(BD_Eventos_Novo!$J:$J,BD_Eventos_Novo!$AB:$AB,DRE!AL$4,BD_Eventos_Novo!$G:$G,"Consumação Mínima")*50%)-(SUMIFS(BD_Eventos_Novo!$K:$K,BD_Eventos_Novo!$AB:$AB,DRE!AL$4,BD_Eventos_Novo!$G:$G,"Consumação Mínima")*50%)-(SUMIFS(BD_Eventos_Novo!$J:$J,BD_Eventos_Novo!$AB:$AB,DRE!AL$4,BD_Eventos_Novo!$G:$G,"Comanda Aberta / Couvert Antecipado")*50%)-(SUMIFS(BD_Eventos_Novo!$K:$K,BD_Eventos_Novo!$AB:$AB,DRE!AL$4,BD_Eventos_Novo!$G:$G,"Comanda Aberta / Couvert Antecipado")*50%)+SUMIFS(Aut_Ajustes_Manuais!$G:$G,Aut_Ajustes_Manuais!$I:$I,DRE!AL$4,Aut_Ajustes_Manuais!$F:$F,"Alimentação") -> 0 | AO9: 170768.9 | AP9: 134979.78 | AQ9: =SUMIFS(Aut_Faturamento_Zig!$F:$F,Aut_Faturamento_Zig!$E:$E,"Alimentos",Aut_Faturamento_Zig!$D:$D,DRE!AO$4)-SUMIFS(Aut_Promocoes_Utilizadas!$G:$G,Aut_Promocoes_Utilizadas!$J:$J,DRE!AO$4,Aut_Promocoes_Utilizadas!$H:$H,"A",Aut_Promocoes_Utilizadas!$I:$I,"Eventos")-SUMIFS(Aut_Descontos!$I:$I,Aut_Descontos!$L:$L,DRE!AO$4)-(SUMIFS(BD_Eventos_Novo!$J:$J,BD_Eventos_Novo!$AB:$AB,DRE!AO$4,BD_Eventos_Novo!$G:$G,"Consumação Mínima")*50%)-(SUMIFS(BD_Eventos_Novo!$K:$K,BD_Eventos_Novo!$AB:$AB,DRE!AO$4,BD_Eventos_Novo!$G:$G,"Consumação Mínima")*50%)-(SUMIFS(BD_Eventos_Novo!$J:$J,BD_Eventos_Novo!$AB:$AB,DRE!AO$4,BD_Eventos_Novo!$G:$G,"Comanda Aberta / Couvert Antecipado")*50%)-(SUMIFS(BD_Eventos_Novo!$K:$K,BD_Eventos_Novo!$AB:$AB,DRE!AO$4,BD_Eventos_Novo!$G:$G,"Comanda Aberta / Couvert Antecipado")*50%)+SUMIFS(Aut_Ajustes_Manuais!$G:$G,Aut_Ajustes_Manuais!$I:$I,DRE!AO$4,Aut_Ajustes_Manuais!$F:$F,"Alimentação") -> 0 | AR9: =SUMIFS($H9:$AO9,$H$5:$AO$5,"<"&MONTH(TODAY()),$H$6:$AO$6,"REAL 25") -> 879122.6 | AS9: =SUMIFS($I9:$AP9,$I$5:$AP$5,"<"&MONTH(TODAY()),$I$6:$AP$6,"ORÇADO ") -> 707608.21 | AT9: =SUMIFS($J9:$AQ9,$J$5:$AQ$5,"<"&MONTH(TODAY()),$J$6:$AQ$6,"REAL 26") -> 862734.1 | AU9: =SUM(H9,K9,N9,Q9,T9,W9,Z9,AC9,AF9,AI9,AL9,AO9) -> 1836477.7 | AV9: =SUM(I9,L9,O9,R9,U9,X9,AA9,AD9,AG9,AJ9,AM9,AP9) -> 1530275.3 | AW9: =SUM(J9,M9,P9,S9,V9,Y9,AB9,AE9,AH9,AK9,AN9,AQ9) -> 894821.6 | AX9: =SUM(H9,K9,N9) -> 407553 | AY9: =SUM(I9,L9,O9) -> 322473.39 | AZ9: =SUM(J9,M9,P9) -> 410765.4 | BA9: =SUM(Q9,T9,W9) -> 471569.6 | BB9: =SUM(R9,U9,X9) -> 385134.82 | BC9: =SUM(S9,V9,Y9) -> 451968.7 | BD9: =SUM(Z9,AC9,AF9) -> 480296.7 | BE9: =SUM(AA9,AD9,AG9) -> 410051.16 | BF9: =SUM(AB9,AE9,AH9) -> 32087.5 | BG9: =SUM(AI9,AL9,AO9) -> 477058.4 | BH9: =SUM(AJ9,AM9,AP9) -> 412615.97 | BI9: =SUM(AK9,AN9,AQ9) -> 0 | BK9: =SUM(I9,L9,O9,R9,U9,X9,AA9,AD9,AG9,AJ9,AM9,AP9) -> 1530275.3 | BL9: =BK9-AV9 -> 0 | BM9: =SUM(J9,M9,P9,S9,V9) -> 713118.8 | BN9: =BM9-AT9 -> -149615.3
A10: Bebida | C10: Estim. Mensal | D10: Preencher base de Faturamento A&B&C | H10: 155838.7 | I10: 156633.25 | J10: =SUMIFS(Aut_Faturamento_Zig!$F:$F,Aut_Faturamento_Zig!$E:$E,"Bebidas",Aut_Faturamento_Zig!$D:$D,DRE!H$4)-SUMIFS(Aut_Promocoes_Utilizadas!$G:$G,Aut_Promocoes_Utilizadas!$J:$J,DRE!H$4,Aut_Promocoes_Utilizadas!$H:$H,"B",Aut_Promocoes_Utilizadas!$I:$I,"Eventos")-SUMIFS(Aut_Descontos!$J:$J,Aut_Descontos!$L:$L,DRE!H$4)-(SUMIFS(BD_Eventos_Novo!$J:$J,BD_Eventos_Novo!$AB:$AB,DRE!H$4,BD_Eventos_Novo!$G:$G,"Consumação Mínima")*50%)-(SUMIFS(BD_Eventos_Novo!$K:$K,BD_Eventos_Novo!$AB:$AB,DRE!H$4,BD_Eventos_Novo!$G:$G,"Consumação Mínima")*50%)-(SUMIFS(BD_Eventos_Novo!$J:$J,BD_Eventos_Novo!$AB:$AB,DRE!H$4,BD_Eventos_Novo!$G:$G,"Comanda Aberta / Couvert Antecipado")*50%)-(SUMIFS(BD_Eventos_Novo!$K:$K,BD_Eventos_Novo!$AB:$AB,DRE!H$4,BD_Eventos_Novo!$G:$G,"Comanda Aberta / Couvert Antecipado")*50%)+SUMIFS(Aut_Ajustes_Manuais!$G:$G,Aut_Ajustes_Manuais!$I:$I,DRE!H$4,Aut_Ajustes_Manuais!$F:$F,"Bebida") -> 184339 | K10: 138871.7 | L10: 148610.83 | M10: =SUMIFS(Aut_Faturamento_Zig!$F:$F,Aut_Faturamento_Zig!$E:$E,"Bebidas",Aut_Faturamento_Zig!$D:$D,DRE!K$4)-SUMIFS(Aut_Promocoes_Utilizadas!$G:$G,Aut_Promocoes_Utilizadas!$J:$J,DRE!K$4,Aut_Promocoes_Utilizadas!$H:$H,"B",Aut_Promocoes_Utilizadas!$I:$I,"Eventos")-SUMIFS(Aut_Descontos!$J:$J,Aut_Descontos!$L:$L,DRE!K$4)-(SUMIFS(BD_Eventos_Novo!$J:$J,BD_Eventos_Novo!$AB:$AB,DRE!K$4,BD_Eventos_Novo!$G:$G,"Consumação Mínima")*50%)-(SUMIFS(BD_Eventos_Novo!$K:$K,BD_Eventos_Novo!$AB:$AB,DRE!K$4,BD_Eventos_Novo!$G:$G,"Consumação Mínima")*50%)-(SUMIFS(BD_Eventos_Novo!$J:$J,BD_Eventos_Novo!$AB:$AB,DRE!K$4,BD_Eventos_Novo!$G:$G,"Comanda Aberta / Couvert Antecipado")*50%)-(SUMIFS(BD_Eventos_Novo!$K:$K,BD_Eventos_Novo!$AB:$AB,DRE!K$4,BD_Eventos_Novo!$G:$G,"Comanda Aberta / Couvert Antecipado")*50%)+SUMIFS(Aut_Ajustes_Manuais!$G:$G,Aut_Ajustes_Manuais!$I:$I,DRE!K$4,Aut_Ajustes_Manuais!$F:$F,"Bebida") -> 150466.3 | N10: 138641.5 | O10: 119223.03 | P10: =SUMIFS(Aut_Faturamento_Zig!$F:$F,Aut_Faturamento_Zig!$E:$E,"Bebidas",Aut_Faturamento_Zig!$D:$D,DRE!N$4)-SUMIFS(Aut_Promocoes_Utilizadas!$G:$G,Aut_Promocoes_Utilizadas!$J:$J,DRE!N$4,Aut_Promocoes_Utilizadas!$H:$H,"B",Aut_Promocoes_Utilizadas!$I:$I,"Eventos")-SUMIFS(Aut_Descontos!$J:$J,Aut_Descontos!$L:$L,DRE!N$4)-(SUMIFS(BD_Eventos_Novo!$J:$J,BD_Eventos_Novo!$AB:$AB,DRE!N$4,BD_Eventos_Novo!$G:$G,"Consumação Mínima")*50%)-(SUMIFS(BD_Eventos_Novo!$K:$K,BD_Eventos_Novo!$AB:$AB,DRE!N$4,BD_Eventos_Novo!$G:$G,"Consumação Mínima")*50%)-(SUMIFS(BD_Eventos_Novo!$J:$J,BD_Eventos_Novo!$AB:$AB,DRE!N$4,BD_Eventos_Novo!$G:$G,"Comanda Aberta / Couvert Antecipado")*50%)-(SUMIFS(BD_Eventos_Novo!$K:$K,BD_Eventos_Novo!$AB:$AB,DRE!N$4,BD_Eventos_Novo!$G:$G,"Comanda Aberta / Couvert Antecipado")*50%)+SUMIFS(Aut_Ajustes_Manuais!$G:$G,Aut_Ajustes_Manuais!$I:$I,DRE!N$4,Aut_Ajustes_Manuais!$F:$F,"Bebida") -> 155776.2 | Q10: 144963.8 | R10: 124073.74 | S10: =SUMIFS(Aut_Faturamento_Zig!$F:$F,Aut_Faturamento_Zig!$E:$E,"Bebidas",Aut_Faturamento_Zig!$D:$D,DRE!Q$4)-SUMIFS(Aut_Promocoes_Utilizadas!$G:$G,Aut_Promocoes_Utilizadas!$J:$J,DRE!Q$4,Aut_Promocoes_Utilizadas!$H:$H,"B",Aut_Promocoes_Utilizadas!$I:$I,"Eventos")-SUMIFS(Aut_Descontos!$J:$J,Aut_Descontos!$L:$L,DRE!Q$4)-(SUMIFS(BD_Eventos_Novo!$J:$J,BD_Eventos_Novo!$AB:$AB,DRE!Q$4,BD_Eventos_Novo!$G:$G,"Consumação Mínima")*50%)-(SUMIFS(BD_Eventos_Novo!$K:$K,BD_Eventos_Novo!$AB:$AB,DRE!Q$4,BD_Eventos_Novo!$G:$G,"Consumação Mínima")*50%)-(SUMIFS(BD_Eventos_Novo!$J:$J,BD_Eventos_Novo!$AB:$AB,DRE!Q$4,BD_Eventos_Novo!$G:$G,"Comanda Aberta / Couvert Antecipado")*50%)-(SUMIFS(BD_Eventos_Novo!$K:$K,BD_Eventos_Novo!$AB:$AB,DRE!Q$4,BD_Eventos_Novo!$G:$G,"Comanda Aberta / Couvert Antecipado")*50%)+SUMIFS(Aut_Ajustes_Manuais!$G:$G,Aut_Ajustes_Manuais!$I:$I,DRE!Q$4,Aut_Ajustes_Manuais!$F:$F,"Bebida") -> 175366.7 | T10: 196200.7 | U10: 202414.66 | V10: =SUMIFS(Aut_Faturamento_Zig!$F:$F,Aut_Faturamento_Zig!$E:$E,"Bebidas",Aut_Faturamento_Zig!$D:$D,DRE!T$4)-SUMIFS(Aut_Promocoes_Utilizadas!$G:$G,Aut_Promocoes_Utilizadas!$J:$J,DRE!T$4,Aut_Promocoes_Utilizadas!$H:$H,"B",Aut_Promocoes_Utilizadas!$I:$I,"Eventos")-SUMIFS(Aut_Descontos!$J:$J,Aut_Descontos!$L:$L,DRE!T$4)-(SUMIFS(BD_Eventos_Novo!$J:$J,BD_Eventos_Novo!$AB:$AB,DRE!T$4,BD_Eventos_Novo!$G:$G,"Consumação Mínima")*50%)-(SUMIFS(BD_Eventos_Novo!$K:$K,BD_Eventos_Novo!$AB:$AB,DRE!T$4,BD_Eventos_Novo!$G:$G,"Consumação Mínima")*50%)-(SUMIFS(BD_Eventos_Novo!$J:$J,BD_Eventos_Novo!$AB:$AB,DRE!T$4,BD_Eventos_Novo!$G:$G,"Comanda Aberta / Couvert Antecipado")*50%)-(SUMIFS(BD_Eventos_Novo!$K:$K,BD_Eventos_Novo!$AB:$AB,DRE!T$4,BD_Eventos_Novo!$G:$G,"Comanda Aberta / Couvert Antecipado")*50%)+SUMIFS(Aut_Ajustes_Manuais!$G:$G,Aut_Ajustes_Manuais!$I:$I,DRE!T$4,Aut_Ajustes_Manuais!$F:$F,"Bebida") -> 170771.1 | W10: 150109.1 | X10: 180459.04 | Y10: =SUMIFS(Aut_Faturamento_Zig!$F:$F,Aut_Faturamento_Zig!$E:$E,"Bebidas",Aut_Faturamento_Zig!$D:$D,DRE!W$4)-SUMIFS(Aut_Promocoes_Utilizadas!$G:$G,Aut_Promocoes_Utilizadas!$J:$J,DRE!W$4,Aut_Promocoes_Utilizadas!$H:$H,"B",Aut_Promocoes_Utilizadas!$I:$I,"Eventos")-SUMIFS(Aut_Descontos!$J:$J,Aut_Descontos!$L:$L,DRE!W$4)-(SUMIFS(BD_Eventos_Novo!$J:$J,BD_Eventos_Novo!$AB:$AB,DRE!W$4,BD_Eventos_Novo!$G:$G,"Consumação Mínima")*50%)-(SUMIFS(BD_Eventos_Novo!$K:$K,BD_Eventos_Novo!$AB:$AB,DRE!W$4,BD_Eventos_Novo!$G:$G,"Consumação Mínima")*50%)-(SUMIFS(BD_Eventos_Novo!$J:$J,BD_Eventos_Novo!$AB:$AB,DRE!W$4,BD_Eventos_Novo!$G:$G,"Comanda Aberta / Couvert Antecipado")*50%)-(SUMIFS(BD_Eventos_Novo!$K:$K,BD_Eventos_Novo!$AB:$AB,DRE!W$4,BD_Eventos_Novo!$G:$G,"Comanda Aberta / Couvert Antecipado")*50%)+SUMIFS(Aut_Ajustes_Manuais!$G:$G,Aut_Ajustes_Manuais!$I:$I,DRE!W$4,Aut_Ajustes_Manuais!$F:$F,"Bebida") -> 166426.7 | Z10: 152662.1 | AA10: 178747.84 | AB10: =SUMIFS(Aut_Faturamento_Zig!$F:$F,Aut_Faturamento_Zig!$E:$E,"Bebidas",Aut_Faturamento_Zig!$D:$D,DRE!Z$4)-SUMIFS(Aut_Promocoes_Utilizadas!$G:$G,Aut_Promocoes_Utilizadas!$J:$J,DRE!Z$4,Aut_Promocoes_Utilizadas!$H:$H,"B",Aut_Promocoes_Utilizadas!$I:$I,"Eventos")-SUMIFS(Aut_Descontos!$J:$J,Aut_Descontos!$L:$L,DRE!Z$4)-(SUMIFS(BD_Eventos_Novo!$J:$J,BD_Eventos_Novo!$AB:$AB,DRE!Z$4,BD_Eventos_Novo!$G:$G,"Consumação Mínima")*50%)-(SUMIFS(BD_Eventos_Novo!$K:$K,BD_Eventos_Novo!$AB:$AB,DRE!Z$4,BD_Eventos_Novo!$G:$G,"Consumação Mínima")*50%)-(SUMIFS(BD_Eventos_Novo!$J:$J,BD_Eventos_Novo!$AB:$AB,DRE!Z$4,BD_Eventos_Novo!$G:$G,"Comanda Aberta / Couvert Antecipado")*50%)-(SUMIFS(BD_Eventos_Novo!$K:$K,BD_Eventos_Novo!$AB:$AB,DRE!Z$4,BD_Eventos_Novo!$G:$G,"Comanda Aberta / Couvert Antecipado")*50%)+SUMIFS(Aut_Ajustes_Manuais!$G:$G,Aut_Ajustes_Manuais!$I:$I,DRE!Z$4,Aut_Ajustes_Manuais!$F:$F,"Bebida") -> 36787.4 | AC10: 194325.2 | AD10: 192906.39 | AE10: =SUMIFS(Aut_Faturamento_Zig!$F:$F,Aut_Faturamento_Zig!$E:$E,"Bebidas",Aut_Faturamento_Zig!$D:$D,DRE!AC$4)-SUMIFS(Aut_Promocoes_Utilizadas!$G:$G,Aut_Promocoes_Utilizadas!$J:$J,DRE!AC$4,Aut_Promocoes_Utilizadas!$H:$H,"B",Aut_Promocoes_Utilizadas!$I:$I,"Eventos")-SUMIFS(Aut_Descontos!$J:$J,Aut_Descontos!$L:$L,DRE!AC$4)-(SUMIFS(BD_Eventos_Novo!$J:$J,BD_Eventos_Novo!$AB:$AB,DRE!AC$4,BD_Eventos_Novo!$G:$G,"Consumação Mínima")*50%)-(SUMIFS(BD_Eventos_Novo!$K:$K,BD_Eventos_Novo!$AB:$AB,DRE!AC$4,BD_Eventos_Novo!$G:$G,"Consumação Mínima")*50%)-(SUMIFS(BD_Eventos_Novo!$J:$J,BD_Eventos_Novo!$AB:$AB,DRE!AC$4,BD_Eventos_Novo!$G:$G,"Comanda Aberta / Couvert Antecipado")*50%)-(SUMIFS(BD_Eventos_Novo!$K:$K,BD_Eventos_Novo!$AB:$AB,DRE!AC$4,BD_Eventos_Novo!$G:$G,"Comanda Aberta / Couvert Antecipado")*50%)+SUMIFS(Aut_Ajustes_Manuais!$G:$G,Aut_Ajustes_Manuais!$I:$I,DRE!AC$4,Aut_Ajustes_Manuais!$F:$F,"Bebida") -> 0 | AF10: 159277.5 | AG10: 168090.24 | AH10: =SUMIFS(Aut_Faturamento_Zig!$F:$F,Aut_Faturamento_Zig!$E:$E,"Bebidas",Aut_Faturamento_Zig!$D:$D,DRE!AF$4)-SUMIFS(Aut_Promocoes_Utilizadas!$G:$G,Aut_Promocoes_Utilizadas!$J:$J,DRE!AF$4,Aut_Promocoes_Utilizadas!$H:$H,"B",Aut_Promocoes_Utilizadas!$I:$I,"Eventos")-SUMIFS(Aut_Descontos!$J:$J,Aut_Descontos!$L:$L,DRE!AF$4)-(SUMIFS(BD_Eventos_Novo!$J:$J,BD_Eventos_Novo!$AB:$AB,DRE!AF$4,BD_Eventos_Novo!$G:$G,"Consumação Mínima")*50%)-(SUMIFS(BD_Eventos_Novo!$K:$K,BD_Eventos_Novo!$AB:$AB,DRE!AF$4,BD_Eventos_Novo!$G:$G,"Consumação Mínima")*50%)-(SUMIFS(BD_Eventos_Novo!$J:$J,BD_Eventos_Novo!$AB:$AB,DRE!AF$4,BD_Eventos_Novo!$G:$G,"Comanda Aberta / Couvert Antecipado")*50%)-(SUMIFS(BD_Eventos_Novo!$K:$K,BD_Eventos_Novo!$AB:$AB,DRE!AF$4,BD_Eventos_Novo!$G:$G,"Comanda Aberta / Couvert Antecipado")*50%)+SUMIFS(Aut_Ajustes_Manuais!$G:$G,Aut_Ajustes_Manuais!$I:$I,DRE!AF$4,Aut_Ajustes_Manuais!$F:$F,"Bebida") -> 0 | AI10: 165615.5 | AJ10: 169150.54 | AK10: =SUMIFS(Aut_Faturamento_Zig!$F:$F,Aut_Faturamento_Zig!$E:$E,"Bebidas",Aut_Faturamento_Zig!$D:$D,DRE!AI$4)-SUMIFS(Aut_Promocoes_Utilizadas!$G:$G,Aut_Promocoes_Utilizadas!$J:$J,DRE!AI$4,Aut_Promocoes_Utilizadas!$H:$H,"B",Aut_Promocoes_Utilizadas!$I:$I,"Eventos")-SUMIFS(Aut_Descontos!$J:$J,Aut_Descontos!$L:$L,DRE!AI$4)-(SUMIFS(BD_Eventos_Novo!$J:$J,BD_Eventos_Novo!$AB:$AB,DRE!AI$4,BD_Eventos_Novo!$G:$G,"Consumação Mínima")*50%)-(SUMIFS(BD_Eventos_Novo!$K:$K,BD_Eventos_Novo!$AB:$AB,DRE!AI$4,BD_Eventos_Novo!$G:$G,"Consumação Mínima")*50%)-(SUMIFS(BD_Eventos_Novo!$J:$J,BD_Eventos_Novo!$AB:$AB,DRE!AI$4,BD_Eventos_Novo!$G:$G,"Comanda Aberta / Couvert Antecipado")*50%)-(SUMIFS(BD_Eventos_Novo!$K:$K,BD_Eventos_Novo!$AB:$AB,DRE!AI$4,BD_Eventos_Novo!$G:$G,"Comanda Aberta / Couvert Antecipado")*50%)+SUMIFS(Aut_Ajustes_Manuais!$G:$G,Aut_Ajustes_Manuais!$I:$I,DRE!AI$4,Aut_Ajustes_Manuais!$F:$F,"Bebida") -> 0 | AL10: 212155.5 | AM10: 196298 | AN10: =SUMIFS(Aut_Faturamento_Zig!$F:$F,Aut_Faturamento_Zig!$E:$E,"Bebidas",Aut_Faturamento_Zig!$D:$D,DRE!AL$4)-SUMIFS(Aut_Promocoes_Utilizadas!$G:$G,Aut_Promocoes_Utilizadas!$J:$J,DRE!AL$4,Aut_Promocoes_Utilizadas!$H:$H,"B",Aut_Promocoes_Utilizadas!$I:$I,"Eventos")-SUMIFS(Aut_Descontos!$J:$J,Aut_Descontos!$L:$L,DRE!AL$4)-(SUMIFS(BD_Eventos_Novo!$J:$J,BD_Eventos_Novo!$AB:$AB,DRE!AL$4,BD_Eventos_Novo!$G:$G,"Consumação Mínima")*50%)-(SUMIFS(BD_Eventos_Novo!$K:$K,BD_Eventos_Novo!$AB:$AB,DRE!AL$4,BD_Eventos_Novo!$G:$G,"Consumação Mínima")*50%)-(SUMIFS(BD_Eventos_Novo!$J:$J,BD_Eventos_Novo!$AB:$AB,DRE!AL$4,BD_Eventos_Novo!$G:$G,"Comanda Aberta / Couvert Antecipado")*50%)-(SUMIFS(BD_Eventos_Novo!$K:$K,BD_Eventos_Novo!$AB:$AB,DRE!AL$4,BD_Eventos_Novo!$G:$G,"Comanda Aberta / Couvert Antecipado")*50%)+SUMIFS(Aut_Ajustes_Manuais!$G:$G,Aut_Ajustes_Manuais!$I:$I,DRE!AL$4,Aut_Ajustes_Manuais!$F:$F,"Bebida") -> 0 | AO10: 238922.8 | AP10: 177671.95 | AQ10: =SUMIFS(Aut_Faturamento_Zig!$F:$F,Aut_Faturamento_Zig!$E:$E,"Bebidas",Aut_Faturamento_Zig!$D:$D,DRE!AO$4)-SUMIFS(Aut_Promocoes_Utilizadas!$G:$G,Aut_Promocoes_Utilizadas!$J:$J,DRE!AO$4,Aut_Promocoes_Utilizadas!$H:$H,"B",Aut_Promocoes_Utilizadas!$I:$I,"Eventos")-SUMIFS(Aut_Descontos!$J:$J,Aut_Descontos!$L:$L,DRE!AO$4)-(SUMIFS(BD_Eventos_Novo!$J:$J,BD_Eventos_Novo!$AB:$AB,DRE!AO$4,BD_Eventos_Novo!$G:$G,"Consumação Mínima")*50%)-(SUMIFS(BD_Eventos_Novo!$K:$K,BD_Eventos_Novo!$AB:$AB,DRE!AO$4,BD_Eventos_Novo!$G:$G,"Consumação Mínima")*50%)-(SUMIFS(BD_Eventos_Novo!$J:$J,BD_Eventos_Novo!$AB:$AB,DRE!AO$4,BD_Eventos_Novo!$G:$G,"Comanda Aberta / Couvert Antecipado")*50%)-(SUMIFS(BD_Eventos_Novo!$K:$K,BD_Eventos_Novo!$AB:$AB,DRE!AO$4,BD_Eventos_Novo!$G:$G,"Comanda Aberta / Couvert Antecipado")*50%)+SUMIFS(Aut_Ajustes_Manuais!$G:$G,Aut_Ajustes_Manuais!$I:$I,DRE!AO$4,Aut_Ajustes_Manuais!$F:$F,"Bebida") -> 0 | AR10: =SUMIFS($H10:$AO10,$H$5:$AO$5,"<"&MONTH(TODAY()),$H$6:$AO$6,"REAL 25") -> 924625.5 | AS10: =SUMIFS($I10:$AP10,$I$5:$AP$5,"<"&MONTH(TODAY()),$I$6:$AP$6,"ORÇADO ") -> 931414.55 | AT10: =SUMIFS($J10:$AQ10,$J$5:$AQ$5,"<"&MONTH(TODAY()),$J$6:$AQ$6,"REAL 26") -> 1003146 | AU10: =SUM(H10,K10,N10,Q10,T10,W10,Z10,AC10,AF10,AI10,AL10,AO10) -> 2047584.1 | AV10: =SUM(I10,L10,O10,R10,U10,X10,AA10,AD10,AG10,AJ10,AM10,AP10) -> 2014279.5 | AW10: =SUM(J10,M10,P10,S10,V10,Y10,AB10,AE10,AH10,AK10,AN10,AQ10) -> 1039933.4 | AX10: =SUM(H10,K10,N10) -> 433351.9 | AY10: =SUM(I10,L10,O10) -> 424467.11 | AZ10: =SUM(J10,M10,P10) -> 490581.5 | BA10: =SUM(Q10,T10,W10) -> 491273.6 | BB10: =SUM(R10,U10,X10) -> 506947.45 | BC10: =SUM(S10,V10,Y10) -> 512564.5 | BD10: =SUM(Z10,AC10,AF10) -> 506264.8 | BE10: =SUM(AA10,AD10,AG10) -> 539744.47 | BF10: =SUM(AB10,AE10,AH10) -> 36787.4 | BG10: =SUM(AI10,AL10,AO10) -> 616693.8 | BH10: =SUM(AJ10,AM10,AP10) -> 543120.49 | BI10: =SUM(AK10,AN10,AQ10) -> 0 | BK10: =SUM(I10,L10,O10,R10,U10,X10,AA10,AD10,AG10,AJ10,AM10,AP10) -> 2014279.5 | BL10: =BK10-AV10 -> 0 | BM10: =SUM(J10,M10,P10,S10,V10) -> 836719.3 | BN10: =BM10-AT10 -> -166426.7
A11: Artístico (couvert/shows) | C11: Estim. Mensal | D11: Preencher base de Faturamento A&B&C | H11: 0 | I11: 46784.293 | J11: =SUMIFS(Aut_Faturamento_Zig!$F:$F,Aut_Faturamento_Zig!$E:$E,"Couvert",Aut_Faturamento_Zig!$D:$D,DRE!H$4)+SUMIFS(Aut_Ajustes_Manuais!$G:$G,Aut_Ajustes_Manuais!$I:$I,DRE!H$4,Aut_Ajustes_Manuais!$F:$F,"Artístico (couvert/shows)") -> 2490 | K11: 0 | L11: 44388.103 | M11: =SUMIFS(Aut_Faturamento_Zig!$F:$F,Aut_Faturamento_Zig!$E:$E,"Couvert",Aut_Faturamento_Zig!$D:$D,DRE!K$4)+SUMIFS(Aut_Ajustes_Manuais!$G:$G,Aut_Ajustes_Manuais!$I:$I,DRE!K$4,Aut_Ajustes_Manuais!$F:$F,"Artístico (couvert/shows)") -> 1365 | N11: 900 | O11: 35610.354 | P11: =SUMIFS(Aut_Faturamento_Zig!$F:$F,Aut_Faturamento_Zig!$E:$E,"Couvert",Aut_Faturamento_Zig!$D:$D,DRE!N$4)+SUMIFS(Aut_Ajustes_Manuais!$G:$G,Aut_Ajustes_Manuais!$I:$I,DRE!N$4,Aut_Ajustes_Manuais!$F:$F,"Artístico (couvert/shows)") -> 1995 | Q11: 1215 | R11: 37059.197 | S11: =SUMIFS(Aut_Faturamento_Zig!$F:$F,Aut_Faturamento_Zig!$E:$E,"Couvert",Aut_Faturamento_Zig!$D:$D,DRE!Q$4)+SUMIFS(Aut_Ajustes_Manuais!$G:$G,Aut_Ajustes_Manuais!$I:$I,DRE!Q$4,Aut_Ajustes_Manuais!$F:$F,"Artístico (couvert/shows)") -> 1290 | T11: 1620 | U11: 60458.601 | V11: =SUMIFS(Aut_Faturamento_Zig!$F:$F,Aut_Faturamento_Zig!$E:$E,"Couvert",Aut_Faturamento_Zig!$D:$D,DRE!T$4)+SUMIFS(Aut_Ajustes_Manuais!$G:$G,Aut_Ajustes_Manuais!$I:$I,DRE!T$4,Aut_Ajustes_Manuais!$F:$F,"Artístico (couvert/shows)") -> 2655 | W11: 225 | X11: 53900.746 | Y11: =SUMIFS(Aut_Faturamento_Zig!$F:$F,Aut_Faturamento_Zig!$E:$E,"Couvert",Aut_Faturamento_Zig!$D:$D,DRE!W$4)+SUMIFS(Aut_Ajustes_Manuais!$G:$G,Aut_Ajustes_Manuais!$I:$I,DRE!W$4,Aut_Ajustes_Manuais!$F:$F,"Artístico (couvert/shows)") -> 1440 | Z11: 0 | AA11: 53389.631 | AB11: =SUMIFS(Aut_Faturamento_Zig!$F:$F,Aut_Faturamento_Zig!$E:$E,"Couvert",Aut_Faturamento_Zig!$D:$D,DRE!Z$4)+SUMIFS(Aut_Ajustes_Manuais!$G:$G,Aut_Ajustes_Manuais!$I:$I,DRE!Z$4,Aut_Ajustes_Manuais!$F:$F,"Artístico (couvert/shows)") -> 480 | AC11: 1890 | AD11: 57618.606 | AE11: =SUMIFS(Aut_Faturamento_Zig!$F:$F,Aut_Faturamento_Zig!$E:$E,"Couvert",Aut_Faturamento_Zig!$D:$D,DRE!AC$4)+SUMIFS(Aut_Ajustes_Manuais!$G:$G,Aut_Ajustes_Manuais!$I:$I,DRE!AC$4,Aut_Ajustes_Manuais!$F:$F,"Artístico (couvert/shows)") -> 0 | AF11: 1815 | AG11: 50206.346 | AH11: =SUMIFS(Aut_Faturamento_Zig!$F:$F,Aut_Faturamento_Zig!$E:$E,"Couvert",Aut_Faturamento_Zig!$D:$D,DRE!AF$4)+SUMIFS(Aut_Ajustes_Manuais!$G:$G,Aut_Ajustes_Manuais!$I:$I,DRE!AF$4,Aut_Ajustes_Manuais!$F:$F,"Artístico (couvert/shows)") -> 0 | AI11: 2055 | AJ11: 50523.046 | AK11: =SUMIFS(Aut_Faturamento_Zig!$F:$F,Aut_Faturamento_Zig!$E:$E,"Couvert",Aut_Faturamento_Zig!$D:$D,DRE!AI$4)+SUMIFS(Aut_Ajustes_Manuais!$G:$G,Aut_Ajustes_Manuais!$I:$I,DRE!AI$4,Aut_Ajustes_Manuais!$F:$F,"Artístico (couvert/shows)") -> 0 | AL11: 2400 | AM11: 58631.633 | AN11: =SUMIFS(Aut_Faturamento_Zig!$F:$F,Aut_Faturamento_Zig!$E:$E,"Couvert",Aut_Faturamento_Zig!$D:$D,DRE!AL$4)+SUMIFS(Aut_Ajustes_Manuais!$G:$G,Aut_Ajustes_Manuais!$I:$I,DRE!AL$4,Aut_Ajustes_Manuais!$F:$F,"Artístico (couvert/shows)") -> 0 | AO11: 1245 | AP11: 53068.278 | AQ11: =SUMIFS(Aut_Faturamento_Zig!$F:$F,Aut_Faturamento_Zig!$E:$E,"Couvert",Aut_Faturamento_Zig!$D:$D,DRE!AO$4)+SUMIFS(Aut_Ajustes_Manuais!$G:$G,Aut_Ajustes_Manuais!$I:$I,DRE!AO$4,Aut_Ajustes_Manuais!$F:$F,"Artístico (couvert/shows)") -> 0 | AR11: =SUMIFS($H11:$AO11,$H$5:$AO$5,"<"&MONTH(TODAY()),$H$6:$AO$6,"REAL 25") -> 3960 | AS11: =SUMIFS($I11:$AP11,$I$5:$AP$5,"<"&MONTH(TODAY()),$I$6:$AP$6,"ORÇADO ") -> 278201.29 | AT11: =SUMIFS($J11:$AQ11,$J$5:$AQ$5,"<"&MONTH(TODAY()),$J$6:$AQ$6,"REAL 26") -> 11235 | AU11: =SUM(H11,K11,N11,Q11,T11,W11,Z11,AC11,AF11,AI11,AL11,AO11) -> 13365 | AV11: =SUM(I11,L11,O11,R11,U11,X11,AA11,AD11,AG11,AJ11,AM11,AP11) -> 601638.83 | AW11: =SUM(J11,M11,P11,S11,V11,Y11,AB11,AE11,AH11,AK11,AN11,AQ11) -> 11715 | AX11: =SUM(H11,K11,N11) -> 900 | AY11: =SUM(I11,L11,O11) -> 126782.75 | AZ11: =SUM(J11,M11,P11) -> 5850 | BA11: =SUM(Q11,T11,W11) -> 3060 | BB11: =SUM(R11,U11,X11) -> 151418.54 | BC11: =SUM(S11,V11,Y11) -> 5385 | BD11: =SUM(Z11,AC11,AF11) -> 3705 | BE11: =SUM(AA11,AD11,AG11) -> 161214.58 | BF11: =SUM(AB11,AE11,AH11) -> 480 | BG11: =SUM(AI11,AL11,AO11) -> 5700 | BH11: =SUM(AJ11,AM11,AP11) -> 162222.96 | BI11: =SUM(AK11,AN11,AQ11) -> 0 | BK11: =SUM(I11,L11,O11,R11,U11,X11,AA11,AD11,AG11,AJ11,AM11,AP11) -> 601638.83 | BL11: =BK11-AV11 -> 0 | BM11: =SUM(J11,M11,P11,S11,V11) -> 9795 | BN11: =BM11-AT11 -> -1440
A12: Gifts | C12: Estim. Mensal | D12: Vendas Lojinha | H12: 1780 | I12: 1958.189 | J12: =SUMIFS(Aut_Faturamento_Zig!$F:$F,Aut_Faturamento_Zig!$E:$E,"Gifts",Aut_Faturamento_Zig!$D:$D,DRE!H$4)+SUMIFS(Aut_Ajustes_Manuais!$G:$G,Aut_Ajustes_Manuais!$I:$I,DRE!H$4,Aut_Ajustes_Manuais!$F:$F,"Gifts") -> 4042 | K12: 1725 | L12: 1857.8948 | M12: =SUMIFS(Aut_Faturamento_Zig!$F:$F,Aut_Faturamento_Zig!$E:$E,"Gifts",Aut_Faturamento_Zig!$D:$D,DRE!K$4)+SUMIFS(Aut_Ajustes_Manuais!$G:$G,Aut_Ajustes_Manuais!$I:$I,DRE!K$4,Aut_Ajustes_Manuais!$F:$F,"Gifts") -> 2212 | N12: 1544 | O12: 1490.496 | P12: =SUMIFS(Aut_Faturamento_Zig!$F:$F,Aut_Faturamento_Zig!$E:$E,"Gifts",Aut_Faturamento_Zig!$D:$D,DRE!N$4)+SUMIFS(Aut_Ajustes_Manuais!$G:$G,Aut_Ajustes_Manuais!$I:$I,DRE!N$4,Aut_Ajustes_Manuais!$F:$F,"Gifts") -> 3551 | Q12: 1607 | R12: 1551.1383 | S12: =SUMIFS(Aut_Faturamento_Zig!$F:$F,Aut_Faturamento_Zig!$E:$E,"Gifts",Aut_Faturamento_Zig!$D:$D,DRE!Q$4)+SUMIFS(Aut_Ajustes_Manuais!$G:$G,Aut_Ajustes_Manuais!$I:$I,DRE!Q$4,Aut_Ajustes_Manuais!$F:$F,"Gifts") -> 1721 | T12: 2472 | U12: 2530.5366 | V12: =SUMIFS(Aut_Faturamento_Zig!$F:$F,Aut_Faturamento_Zig!$E:$E,"Gifts",Aut_Faturamento_Zig!$D:$D,DRE!T$4)+SUMIFS(Aut_Ajustes_Manuais!$G:$G,Aut_Ajustes_Manuais!$I:$I,DRE!T$4,Aut_Ajustes_Manuais!$F:$F,"Gifts") -> 1350 | W12: 1478 | X12: 2256.053 | Y12: =SUMIFS(Aut_Faturamento_Zig!$F:$F,Aut_Faturamento_Zig!$E:$E,"Gifts",Aut_Faturamento_Zig!$D:$D,DRE!W$4)+SUMIFS(Aut_Ajustes_Manuais!$G:$G,Aut_Ajustes_Manuais!$I:$I,DRE!W$4,Aut_Ajustes_Manuais!$F:$F,"Gifts") -> 937 | Z12: 1644 | AA12: 2234.66 | AB12: =SUMIFS(Aut_Faturamento_Zig!$F:$F,Aut_Faturamento_Zig!$E:$E,"Gifts",Aut_Faturamento_Zig!$D:$D,DRE!Z$4)+SUMIFS(Aut_Ajustes_Manuais!$G:$G,Aut_Ajustes_Manuais!$I:$I,DRE!Z$4,Aut_Ajustes_Manuais!$F:$F,"Gifts") -> 48 | AC12: 1691 | AD12: 2411.6666 | AE12: =SUMIFS(Aut_Faturamento_Zig!$F:$F,Aut_Faturamento_Zig!$E:$E,"Gifts",Aut_Faturamento_Zig!$D:$D,DRE!AC$4)+SUMIFS(Aut_Ajustes_Manuais!$G:$G,Aut_Ajustes_Manuais!$I:$I,DRE!AC$4,Aut_Ajustes_Manuais!$F:$F,"Gifts") -> 0 | AF12: 1649 | AG12: 2101.4214 | AH12: =SUMIFS(Aut_Faturamento_Zig!$F:$F,Aut_Faturamento_Zig!$E:$E,"Gifts",Aut_Faturamento_Zig!$D:$D,DRE!AF$4)+SUMIFS(Aut_Ajustes_Manuais!$G:$G,Aut_Ajustes_Manuais!$I:$I,DRE!AF$4,Aut_Ajustes_Manuais!$F:$F,"Gifts") -> 0 | AI12: 1802 | AJ12: 2114.6771 | AK12: =SUMIFS(Aut_Faturamento_Zig!$F:$F,Aut_Faturamento_Zig!$E:$E,"Gifts",Aut_Faturamento_Zig!$D:$D,DRE!AI$4)+SUMIFS(Aut_Ajustes_Manuais!$G:$G,Aut_Ajustes_Manuais!$I:$I,DRE!AI$4,Aut_Ajustes_Manuais!$F:$F,"Gifts") -> 0 | AL12: 4696 | AM12: 2454.0676 | AN12: =SUMIFS(Aut_Faturamento_Zig!$F:$F,Aut_Faturamento_Zig!$E:$E,"Gifts",Aut_Faturamento_Zig!$D:$D,DRE!AL$4)+SUMIFS(Aut_Ajustes_Manuais!$G:$G,Aut_Ajustes_Manuais!$I:$I,DRE!AL$4,Aut_Ajustes_Manuais!$F:$F,"Gifts") -> 0 | AO12: 5340 | AP12: 2221.2095 | AQ12: =SUMIFS(Aut_Faturamento_Zig!$F:$F,Aut_Faturamento_Zig!$E:$E,"Gifts",Aut_Faturamento_Zig!$D:$D,DRE!AO$4)+SUMIFS(Aut_Ajustes_Manuais!$G:$G,Aut_Ajustes_Manuais!$I:$I,DRE!AO$4,Aut_Ajustes_Manuais!$F:$F,"Gifts") -> 0 | AR12: =SUMIFS($H12:$AO12,$H$5:$AO$5,"<"&MONTH(TODAY()),$H$6:$AO$6,"REAL 25") -> 10606 | AS12: =SUMIFS($I12:$AP12,$I$5:$AP$5,"<"&MONTH(TODAY()),$I$6:$AP$6,"ORÇADO ") -> 11644.308 | AT12: =SUMIFS($J12:$AQ12,$J$5:$AQ$5,"<"&MONTH(TODAY()),$J$6:$AQ$6,"REAL 26") -> 13813 | AU12: =SUM(H12,K12,N12,Q12,T12,W12,Z12,AC12,AF12,AI12,AL12,AO12) -> 27428 | AV12: =SUM(I12,L12,O12,R12,U12,X12,AA12,AD12,AG12,AJ12,AM12,AP12) -> 25182.01 | AW12: =SUM(J12,M12,P12,S12,V12,Y12,AB12,AE12,AH12,AK12,AN12,AQ12) -> 13861 | AX12: =SUM(H12,K12,N12) -> 5049 | AY12: =SUM(I12,L12,O12) -> 5306.5798 | AZ12: =SUM(J12,M12,P12) -> 9805 | BA12: =SUM(Q12,T12,W12) -> 5557 | BB12: =SUM(R12,U12,X12) -> 6337.728 | BC12: =SUM(S12,V12,Y12) -> 4008 | BD12: =SUM(Z12,AC12,AF12) -> 4984 | BE12: =SUM(AA12,AD12,AG12) -> 6747.748 | BF12: =SUM(AB12,AE12,AH12) -> 48 | BG12: =SUM(AI12,AL12,AO12) -> 11838 | BH12: =SUM(AJ12,AM12,AP12) -> 6789.9542 | BI12: =SUM(AK12,AN12,AQ12) -> 0 | BK12: =SUM(I12,L12,O12,R12,U12,X12,AA12,AD12,AG12,AJ12,AM12,AP12) -> 25182.01 | BL12: =BK12-AV12 -> 0 | BM12: =SUM(J12,M12,P12,S12,V12) -> 12876 | BN12: =BM12-AT12 -> -937
A13: Serviço | C13: Estim. Mensal | D13: Gorjeta Fórmula | E13: 13% sobre A&B&C | H13: 38256.59 | I13: 38286.93 | J13: =SUMIFS(Aut_Faturamento_Zig!$F:$F,Aut_Faturamento_Zig!$E:$E,"Serviço",Aut_Faturamento_Zig!$D:$D,DRE!H$4)+SUMIFS(Aut_Ajustes_Manuais!$G:$G,Aut_Ajustes_Manuais!$I:$I,DRE!H$4,Aut_Ajustes_Manuais!$F:$F,"Serviço") -> 43508.15 | K13: 34751.18 | L13: 36325.956 | M13: =SUMIFS(Aut_Faturamento_Zig!$F:$F,Aut_Faturamento_Zig!$E:$E,"Serviço",Aut_Faturamento_Zig!$D:$D,DRE!K$4)+SUMIFS(Aut_Ajustes_Manuais!$G:$G,Aut_Ajustes_Manuais!$I:$I,DRE!K$4,Aut_Ajustes_Manuais!$F:$F,"Serviço") -> 35399.38 | N13: 34535.35 | O13: 29142.497 | P13: =SUMIFS(Aut_Faturamento_Zig!$F:$F,Aut_Faturamento_Zig!$E:$E,"Serviço",Aut_Faturamento_Zig!$D:$D,DRE!N$4)+SUMIFS(Aut_Ajustes_Manuais!$G:$G,Aut_Ajustes_Manuais!$I:$I,DRE!N$4,Aut_Ajustes_Manuais!$F:$F,"Serviço") -> 37123.69 | Q13: 36941.19 | R13: 30328.189 | S13: =SUMIFS(Aut_Faturamento_Zig!$F:$F,Aut_Faturamento_Zig!$E:$E,"Serviço",Aut_Faturamento_Zig!$D:$D,DRE!Q$4)+SUMIFS(Aut_Ajustes_Manuais!$G:$G,Aut_Ajustes_Manuais!$I:$I,DRE!Q$4,Aut_Ajustes_Manuais!$F:$F,"Serviço") -> 40637.15 | T13: 48405.33 | U13: 49477.594 | V13: =SUMIFS(Aut_Faturamento_Zig!$F:$F,Aut_Faturamento_Zig!$E:$E,"Serviço",Aut_Faturamento_Zig!$D:$D,DRE!T$4)+SUMIFS(Aut_Ajustes_Manuais!$G:$G,Aut_Ajustes_Manuais!$I:$I,DRE!T$4,Aut_Ajustes_Manuais!$F:$F,"Serviço") -> 41612.77 | W13: 36988.57 | X13: 44110.832 | Y13: =SUMIFS(Aut_Faturamento_Zig!$F:$F,Aut_Faturamento_Zig!$E:$E,"Serviço",Aut_Faturamento_Zig!$D:$D,DRE!W$4)+SUMIFS(Aut_Ajustes_Manuais!$G:$G,Aut_Ajustes_Manuais!$I:$I,DRE!W$4,Aut_Ajustes_Manuais!$F:$F,"Serviço") -> 40068.77 | Z13: 39419.73 | AA13: 43692.55 | AB13: =SUMIFS(Aut_Faturamento_Zig!$F:$F,Aut_Faturamento_Zig!$E:$E,"Serviço",Aut_Faturamento_Zig!$D:$D,DRE!Z$4)+SUMIFS(Aut_Ajustes_Manuais!$G:$G,Aut_Ajustes_Manuais!$I:$I,DRE!Z$4,Aut_Ajustes_Manuais!$F:$F,"Serviço") -> 8709.55 | AC13: 46429.36 | AD13: 47153.423 | AE13: =SUMIFS(Aut_Faturamento_Zig!$F:$F,Aut_Faturamento_Zig!$E:$E,"Serviço",Aut_Faturamento_Zig!$D:$D,DRE!AC$4)+SUMIFS(Aut_Ajustes_Manuais!$G:$G,Aut_Ajustes_Manuais!$I:$I,DRE!AC$4,Aut_Ajustes_Manuais!$F:$F,"Serviço") -> 0 | AF13: 38996.34 | AG13: 41087.441 | AH13: =SUMIFS(Aut_Faturamento_Zig!$F:$F,Aut_Faturamento_Zig!$E:$E,"Serviço",Aut_Faturamento_Zig!$D:$D,DRE!AF$4)+SUMIFS(Aut_Ajustes_Manuais!$G:$G,Aut_Ajustes_Manuais!$I:$I,DRE!AF$4,Aut_Ajustes_Manuais!$F:$F,"Serviço") -> 0 | AI13: 40943.88 | AJ13: 41346.619 | AK13: =SUMIFS(Aut_Faturamento_Zig!$F:$F,Aut_Faturamento_Zig!$E:$E,"Serviço",Aut_Faturamento_Zig!$D:$D,DRE!AI$4)+SUMIFS(Aut_Ajustes_Manuais!$G:$G,Aut_Ajustes_Manuais!$I:$I,DRE!AI$4,Aut_Ajustes_Manuais!$F:$F,"Serviço") -> 0 | AL13: 47415.6 | AM13: 47982.455 | AN13: =SUMIFS(Aut_Faturamento_Zig!$F:$F,Aut_Faturamento_Zig!$E:$E,"Serviço",Aut_Faturamento_Zig!$D:$D,DRE!AL$4)+SUMIFS(Aut_Ajustes_Manuais!$G:$G,Aut_Ajustes_Manuais!$I:$I,DRE!AL$4,Aut_Ajustes_Manuais!$F:$F,"Serviço") -> 0 | AO13: 52286.04 | AP13: 43429.564 | AQ13: =SUMIFS(Aut_Faturamento_Zig!$F:$F,Aut_Faturamento_Zig!$E:$E,"Serviço",Aut_Faturamento_Zig!$D:$D,DRE!AO$4)+SUMIFS(Aut_Ajustes_Manuais!$G:$G,Aut_Ajustes_Manuais!$I:$I,DRE!AO$4,Aut_Ajustes_Manuais!$F:$F,"Serviço") -> 0 | AR13: =SUMIFS($H13:$AO13,$H$5:$AO$5,"<"&MONTH(TODAY()),$H$6:$AO$6,"REAL 25") -> 229878.21 | AS13: =SUMIFS($I13:$AP13,$I$5:$AP$5,"<"&MONTH(TODAY()),$I$6:$AP$6,"ORÇADO ") -> 227672 | AT13: =SUMIFS($J13:$AQ13,$J$5:$AQ$5,"<"&MONTH(TODAY()),$J$6:$AQ$6,"REAL 26") -> 238349.91 | AU13: =SUM(H13,K13,N13,Q13,T13,W13,Z13,AC13,AF13,AI13,AL13,AO13) -> 495369.16 | AV13: =SUM(I13,L13,O13,R13,U13,X13,AA13,AD13,AG13,AJ13,AM13,AP13) -> 492364.05 | AW13: =SUM(J13,M13,P13,S13,V13,Y13,AB13,AE13,AH13,AK13,AN13,AQ13) -> 247059.46 | AX13: =SUM(H13,K13,N13) -> 107543.12 | AY13: =SUM(I13,L13,O13) -> 103755.38 | AZ13: =SUM(J13,M13,P13) -> 116031.22 | BA13: =SUM(Q13,T13,W13) -> 122335.09 | BB13: =SUM(R13,U13,X13) -> 123916.61 | BC13: =SUM(S13,V13,Y13) -> 122318.69 | BD13: =SUM(Z13,AC13,AF13) -> 124845.43 | BE13: =SUM(AA13,AD13,AG13) -> 131933.41 | BF13: =SUM(AB13,AE13,AH13) -> 8709.55 | BG13: =SUM(AI13,AL13,AO13) -> 140645.52 | BH13: =SUM(AJ13,AM13,AP13) -> 132758.64 | BI13: =SUM(AK13,AN13,AQ13) -> 0 | BK13: =SUM(I13,L13,O13,R13,U13,X13,AA13,AD13,AG13,AJ13,AM13,AP13) -> 492364.05 | BL13: =BK13-AV13 -> 0 | BM13: =SUM(J13,M13,P13,S13,V13) -> 198281.14 | BN13: =BM13-AT13 -> -40068.77
A14: Eventos A&B | C14: Estim. Mensal | D14: Preencher base de Eventos | H14: 0 | I14: 8395.8695 | J14: =SUMIFS(BD_Eventos_Novo!$J:$J,BD_Eventos_Novo!$AB:$AB,DRE!H$4)+SUMIFS(BD_Eventos_Novo!$K:$K,BD_Eventos_Novo!$AB:$AB,DRE!H$4)+SUMIFS(Aut_Ajustes_Manuais!$G:$G,Aut_Ajustes_Manuais!$I:$I,DRE!H$4,Aut_Ajustes_Manuais!$F:$F,"Eventos A&B") -> 0 | K14: 0 | L14: 7965.8512 | M14: =SUMIFS(BD_Eventos_Novo!$J:$J,BD_Eventos_Novo!$AB:$AB,DRE!K$4)+SUMIFS(BD_Eventos_Novo!$K:$K,BD_Eventos_Novo!$AB:$AB,DRE!K$4)+SUMIFS(Aut_Ajustes_Manuais!$G:$G,Aut_Ajustes_Manuais!$I:$I,DRE!K$4,Aut_Ajustes_Manuais!$F:$F,"Eventos A&B") -> 0 | N14: 0 | O14: 6390.6039 | P14: =SUMIFS(BD_Eventos_Novo!$J:$J,BD_Eventos_Novo!$AB:$AB,DRE!N$4)+SUMIFS(BD_Eventos_Novo!$K:$K,BD_Eventos_Novo!$AB:$AB,DRE!N$4)+SUMIFS(Aut_Ajustes_Manuais!$G:$G,Aut_Ajustes_Manuais!$I:$I,DRE!N$4,Aut_Ajustes_Manuais!$F:$F,"Eventos A&B") -> 0 | Q14: 0 | R14: 6650.612 | S14: =SUMIFS(BD_Eventos_Novo!$J:$J,BD_Eventos_Novo!$AB:$AB,DRE!Q$4)+SUMIFS(BD_Eventos_Novo!$K:$K,BD_Eventos_Novo!$AB:$AB,DRE!Q$4)+SUMIFS(Aut_Ajustes_Manuais!$G:$G,Aut_Ajustes_Manuais!$I:$I,DRE!Q$4,Aut_Ajustes_Manuais!$F:$F,"Eventos A&B") -> 0 | T14: 0 | U14: 10849.849 | V14: =SUMIFS(BD_Eventos_Novo!$J:$J,BD_Eventos_Novo!$AB:$AB,DRE!T$4)+SUMIFS(BD_Eventos_Novo!$K:$K,BD_Eventos_Novo!$AB:$AB,DRE!T$4)+SUMIFS(Aut_Ajustes_Manuais!$G:$G,Aut_Ajustes_Manuais!$I:$I,DRE!T$4,Aut_Ajustes_Manuais!$F:$F,"Eventos A&B") -> 0 | W14: 0 | X14: 9672.9821 | Y14: =SUMIFS(BD_Eventos_Novo!$J:$J,BD_Eventos_Novo!$AB:$AB,DRE!W$4)+SUMIFS(BD_Eventos_Novo!$K:$K,BD_Eventos_Novo!$AB:$AB,DRE!W$4)+SUMIFS(Aut_Ajustes_Manuais!$G:$G,Aut_Ajustes_Manuais!$I:$I,DRE!W$4,Aut_Ajustes_Manuais!$F:$F,"Eventos A&B") -> 0 | Z14: 0 | AA14: 9581.2578 | AB14: =SUMIFS(BD_Eventos_Novo!$J:$J,BD_Eventos_Novo!$AB:$AB,DRE!Z$4)+SUMIFS(BD_Eventos_Novo!$K:$K,BD_Eventos_Novo!$AB:$AB,DRE!Z$4)+SUMIFS(Aut_Ajustes_Manuais!$G:$G,Aut_Ajustes_Manuais!$I:$I,DRE!Z$4,Aut_Ajustes_Manuais!$F:$F,"Eventos A&B") -> 0 | AC14: 0 | AD14: 10340.186 | AE14: =SUMIFS(BD_Eventos_Novo!$J:$J,BD_Eventos_Novo!$AB:$AB,DRE!AC$4)+SUMIFS(BD_Eventos_Novo!$K:$K,BD_Eventos_Novo!$AB:$AB,DRE!AC$4)+SUMIFS(Aut_Ajustes_Manuais!$G:$G,Aut_Ajustes_Manuais!$I:$I,DRE!AC$4,Aut_Ajustes_Manuais!$F:$F,"Eventos A&B") -> 0 | AF14: 0 | AG14: 9009.9883 | AH14: =SUMIFS(BD_Eventos_Novo!$J:$J,BD_Eventos_Novo!$AB:$AB,DRE!AF$4)+SUMIFS(BD_Eventos_Novo!$K:$K,BD_Eventos_Novo!$AB:$AB,DRE!AF$4)+SUMIFS(Aut_Ajustes_Manuais!$G:$G,Aut_Ajustes_Manuais!$I:$I,DRE!AF$4,Aut_Ajustes_Manuais!$F:$F,"Eventos A&B") -> 0 | AI14: 0 | AJ14: 9066.8229 | AK14: =SUMIFS(BD_Eventos_Novo!$J:$J,BD_Eventos_Novo!$AB:$AB,DRE!AI$4)+SUMIFS(BD_Eventos_Novo!$K:$K,BD_Eventos_Novo!$AB:$AB,DRE!AI$4)+SUMIFS(Aut_Ajustes_Manuais!$G:$G,Aut_Ajustes_Manuais!$I:$I,DRE!AI$4,Aut_Ajustes_Manuais!$F:$F,"Eventos A&B") -> 0 | AL14: 6400 | AM14: 10521.983 | AN14: =SUMIFS(BD_Eventos_Novo!$J:$J,BD_Eventos_Novo!$AB:$AB,DRE!AL$4)+SUMIFS(BD_Eventos_Novo!$K:$K,BD_Eventos_Novo!$AB:$AB,DRE!AL$4)+SUMIFS(Aut_Ajustes_Manuais!$G:$G,Aut_Ajustes_Manuais!$I:$I,DRE!AL$4,Aut_Ajustes_Manuais!$F:$F,"Eventos A&B") -> 0 | AO14: 10500 | AP14: 9523.5882 | AQ14: =SUMIFS(BD_Eventos_Novo!$J:$J,BD_Eventos_Novo!$AB:$AB,DRE!AO$4)+SUMIFS(BD_Eventos_Novo!$K:$K,BD_Eventos_Novo!$AB:$AB,DRE!AO$4)+SUMIFS(Aut_Ajustes_Manuais!$G:$G,Aut_Ajustes_Manuais!$I:$I,DRE!AO$4,Aut_Ajustes_Manuais!$F:$F,"Eventos A&B") -> 0 | AR14: =SUMIFS($H14:$AO14,$H$5:$AO$5,"<"&MONTH(TODAY()),$H$6:$AO$6,"REAL 25") -> 0 | AS14: =SUMIFS($I14:$AP14,$I$5:$AP$5,"<"&MONTH(TODAY()),$I$6:$AP$6,"ORÇADO ") -> 49925.768 | AT14: =SUMIFS($J14:$AQ14,$J$5:$AQ$5,"<"&MONTH(TODAY()),$J$6:$AQ$6,"REAL 26") -> 0 | AU14: =SUM(H14,K14,N14,Q14,T14,W14,Z14,AC14,AF14,AI14,AL14,AO14) -> 16900 | AV14: =SUM(I14,L14,O14,R14,U14,X14,AA14,AD14,AG14,AJ14,AM14,AP14) -> 107969.59 | AW14: =SUM(J14,M14,P14,S14,V14,Y14,AB14,AE14,AH14,AK14,AN14,AQ14) -> 0 | AX14: =SUM(H14,K14,N14) -> 0 | AY14: =SUM(I14,L14,O14) -> 22752.325 | AZ14: =SUM(J14,M14,P14) -> 0 | BA14: =SUM(Q14,T14,W14) -> 0 | BB14: =SUM(R14,U14,X14) -> 27173.443 | BC14: =SUM(S14,V14,Y14) -> 0 | BD14: =SUM(Z14,AC14,AF14) -> 0 | BE14: =SUM(AA14,AD14,AG14) -> 28931.432 | BF14: =SUM(AB14,AE14,AH14) -> 0 | BG14: =SUM(AI14,AL14,AO14) -> 16900 | BH14: =SUM(AJ14,AM14,AP14) -> 29112.394 | BI14: =SUM(AK14,AN14,AQ14) -> 0 | BK14: =SUM(I14,L14,O14,R14,U14,X14,AA14,AD14,AG14,AJ14,AM14,AP14) -> 107969.59 | BL14: =BK14-AV14 -> 0 | BM14: =SUM(J14,M14,P14,S14,V14) -> 0 | BN14: =BM14-AT14 -> 0
A15: Eventos Couvert | C15: Estim. Mensal | D15: Preencher base de Eventos | H15: 0 | I15: 1185.5929 | J15: =SUMIFS(BD_Eventos_Novo!$M:$M,BD_Eventos_Novo!$AB:$AB,DRE!H$4)+SUMIFS(BD_Eventos_Novo!$N:$N,BD_Eventos_Novo!$AB:$AB,DRE!H$4)+SUMIFS(BD_Eventos_Novo!$O:$O,BD_Eventos_Novo!$AB:$AB,DRE!H$4)+SUMIFS(Aut_Ajustes_Manuais!$G:$G,Aut_Ajustes_Manuais!$I:$I,DRE!H$4,Aut_Ajustes_Manuais!$F:$F,"Eventos Couvert") -> 0 | K15: 0 | L15: 1124.8694 | M15: =SUMIFS(BD_Eventos_Novo!$M:$M,BD_Eventos_Novo!$AB:$AB,DRE!K$4)+SUMIFS(BD_Eventos_Novo!$N:$N,BD_Eventos_Novo!$AB:$AB,DRE!K$4)+SUMIFS(BD_Eventos_Novo!$O:$O,BD_Eventos_Novo!$AB:$AB,DRE!K$4)+SUMIFS(Aut_Ajustes_Manuais!$G:$G,Aut_Ajustes_Manuais!$I:$I,DRE!K$4,Aut_Ajustes_Manuais!$F:$F,"Eventos Couvert") -> 0 | N15: 0 | O15: 902.42645 | P15: =SUMIFS(BD_Eventos_Novo!$M:$M,BD_Eventos_Novo!$AB:$AB,DRE!N$4)+SUMIFS(BD_Eventos_Novo!$N:$N,BD_Eventos_Novo!$AB:$AB,DRE!N$4)+SUMIFS(BD_Eventos_Novo!$O:$O,BD_Eventos_Novo!$AB:$AB,DRE!N$4)+SUMIFS(Aut_Ajustes_Manuais!$G:$G,Aut_Ajustes_Manuais!$I:$I,DRE!N$4,Aut_Ajustes_Manuais!$F:$F,"Eventos Couvert") -> 0 | Q15: 0 | R15: 939.14257 | S15: =SUMIFS(BD_Eventos_Novo!$M:$M,BD_Eventos_Novo!$AB:$AB,DRE!Q$4)+SUMIFS(BD_Eventos_Novo!$N:$N,BD_Eventos_Novo!$AB:$AB,DRE!Q$4)+SUMIFS(BD_Eventos_Novo!$O:$O,BD_Eventos_Novo!$AB:$AB,DRE!Q$4)+SUMIFS(Aut_Ajustes_Manuais!$G:$G,Aut_Ajustes_Manuais!$I:$I,DRE!Q$4,Aut_Ajustes_Manuais!$F:$F,"Eventos Couvert") -> 0 | T15: 0 | U15: 1532.123 | V15: =SUMIFS(BD_Eventos_Novo!$M:$M,BD_Eventos_Novo!$AB:$AB,DRE!T$4)+SUMIFS(BD_Eventos_Novo!$N:$N,BD_Eventos_Novo!$AB:$AB,DRE!T$4)+SUMIFS(BD_Eventos_Novo!$O:$O,BD_Eventos_Novo!$AB:$AB,DRE!T$4)+SUMIFS(Aut_Ajustes_Manuais!$G:$G,Aut_Ajustes_Manuais!$I:$I,DRE!T$4,Aut_Ajustes_Manuais!$F:$F,"Eventos Couvert") -> 0 | W15: 0 | X15: 1365.9358 | Y15: =SUMIFS(BD_Eventos_Novo!$M:$M,BD_Eventos_Novo!$AB:$AB,DRE!W$4)+SUMIFS(BD_Eventos_Novo!$N:$N,BD_Eventos_Novo!$AB:$AB,DRE!W$4)+SUMIFS(BD_Eventos_Novo!$O:$O,BD_Eventos_Novo!$AB:$AB,DRE!W$4)+SUMIFS(Aut_Ajustes_Manuais!$G:$G,Aut_Ajustes_Manuais!$I:$I,DRE!W$4,Aut_Ajustes_Manuais!$F:$F,"Eventos Couvert") -> 0 | Z15: 0 | AA15: 1352.9833 | AB15: =SUMIFS(BD_Eventos_Novo!$M:$M,BD_Eventos_Novo!$AB:$AB,DRE!Z$4)+SUMIFS(BD_Eventos_Novo!$N:$N,BD_Eventos_Novo!$AB:$AB,DRE!Z$4)+SUMIFS(BD_Eventos_Novo!$O:$O,BD_Eventos_Novo!$AB:$AB,DRE!Z$4)+SUMIFS(Aut_Ajustes_Manuais!$G:$G,Aut_Ajustes_Manuais!$I:$I,DRE!Z$4,Aut_Ajustes_Manuais!$F:$F,"Eventos Couvert") -> 0 | AC15: 0 | AD15: 1460.1527 | AE15: =SUMIFS(BD_Eventos_Novo!$M:$M,BD_Eventos_Novo!$AB:$AB,DRE!AC$4)+SUMIFS(BD_Eventos_Novo!$N:$N,BD_Eventos_Novo!$AB:$AB,DRE!AC$4)+SUMIFS(BD_Eventos_Novo!$O:$O,BD_Eventos_Novo!$AB:$AB,DRE!AC$4)+SUMIFS(Aut_Ajustes_Manuais!$G:$G,Aut_Ajustes_Manuais!$I:$I,DRE!AC$4,Aut_Ajustes_Manuais!$F:$F,"Eventos Couvert") -> 0 | AF15: 0 | AG15: 1272.3135 | AH15: =SUMIFS(BD_Eventos_Novo!$M:$M,BD_Eventos_Novo!$AB:$AB,DRE!AF$4)+SUMIFS(BD_Eventos_Novo!$N:$N,BD_Eventos_Novo!$AB:$AB,DRE!AF$4)+SUMIFS(BD_Eventos_Novo!$O:$O,BD_Eventos_Novo!$AB:$AB,DRE!AF$4)+SUMIFS(Aut_Ajustes_Manuais!$G:$G,Aut_Ajustes_Manuais!$I:$I,DRE!AF$4,Aut_Ajustes_Manuais!$F:$F,"Eventos Couvert") -> 0 | AI15: 0 | AJ15: 1280.3392 | AK15: =SUMIFS(BD_Eventos_Novo!$M:$M,BD_Eventos_Novo!$AB:$AB,DRE!AI$4)+SUMIFS(BD_Eventos_Novo!$N:$N,BD_Eventos_Novo!$AB:$AB,DRE!AI$4)+SUMIFS(BD_Eventos_Novo!$O:$O,BD_Eventos_Novo!$AB:$AB,DRE!AI$4)+SUMIFS(Aut_Ajustes_Manuais!$G:$G,Aut_Ajustes_Manuais!$I:$I,DRE!AI$4,Aut_Ajustes_Manuais!$F:$F,"Eventos Couvert") -> 0 | AL15: 0 | AM15: 1485.8245 | AN15: =SUMIFS(BD_Eventos_Novo!$M:$M,BD_Eventos_Novo!$AB:$AB,DRE!AL$4)+SUMIFS(BD_Eventos_Novo!$N:$N,BD_Eventos_Novo!$AB:$AB,DRE!AL$4)+SUMIFS(BD_Eventos_Novo!$O:$O,BD_Eventos_Novo!$AB:$AB,DRE!AL$4)+SUMIFS(Aut_Ajustes_Manuais!$G:$G,Aut_Ajustes_Manuais!$I:$I,DRE!AL$4,Aut_Ajustes_Manuais!$F:$F,"Eventos Couvert") -> 0 | AO15: 0 | AP15: 1344.8397 | AQ15: =SUMIFS(BD_Eventos_Novo!$M:$M,BD_Eventos_Novo!$AB:$AB,DRE!AO$4)+SUMIFS(BD_Eventos_Novo!$N:$N,BD_Eventos_Novo!$AB:$AB,DRE!AO$4)+SUMIFS(BD_Eventos_Novo!$O:$O,BD_Eventos_Novo!$AB:$AB,DRE!AO$4)+SUMIFS(Aut_Ajustes_Manuais!$G:$G,Aut_Ajustes_Manuais!$I:$I,DRE!AO$4,Aut_Ajustes_Manuais!$F:$F,"Eventos Couvert") -> 0 | AR15: =SUMIFS($H15:$AO15,$H$5:$AO$5,"<"&MONTH(TODAY()),$H$6:$AO$6,"REAL 25") -> 0 | AS15: =SUMIFS($I15:$AP15,$I$5:$AP$5,"<"&MONTH(TODAY()),$I$6:$AP$6,"ORÇADO ") -> 7050.0901 | AT15: =SUMIFS($J15:$AQ15,$J$5:$AQ$5,"<"&MONTH(TODAY()),$J$6:$AQ$6,"REAL 26") -> 0 | AU15: =SUM(H15,K15,N15,Q15,T15,W15,Z15,AC15,AF15,AI15,AL15,AO15) -> 0 | AV15: =SUM(I15,L15,O15,R15,U15,X15,AA15,AD15,AG15,AJ15,AM15,AP15) -> 15246.543 | AW15: =SUM(J15,M15,P15,S15,V15,Y15,AB15,AE15,AH15,AK15,AN15,AQ15) -> 0 | AX15: =SUM(H15,K15,N15) -> 0 | AY15: =SUM(I15,L15,O15) -> 3212.8888 | AZ15: =SUM(J15,M15,P15) -> 0 | BA15: =SUM(Q15,T15,W15) -> 0 | BB15: =SUM(R15,U15,X15) -> 3837.2014 | BC15: =SUM(S15,V15,Y15) -> 0 | BD15: =SUM(Z15,AC15,AF15) -> 0 | BE15: =SUM(AA15,AD15,AG15) -> 4085.4495 | BF15: =SUM(AB15,AE15,AH15) -> 0 | BG15: =SUM(AI15,AL15,AO15) -> 0 | BH15: =SUM(AJ15,AM15,AP15) -> 4111.0034 | BI15: =SUM(AK15,AN15,AQ15) -> 0 | BK15: =SUM(I15,L15,O15,R15,U15,X15,AA15,AD15,AG15,AJ15,AM15,AP15) -> 15246.543 | BL15: =BK15-AV15 -> 0 | BM15: =SUM(J15,M15,P15,S15,V15) -> 0 | BN15: =BM15-AT15 -> 0
